<?xml version="1.0" encoding="utf-8"?>
<!-- =================================================================================== -->
<!-- |    This document was autogenerated by xacro from widowxl.urdf.xacro             | -->
<!-- |    EDITING THIS FILE BY HAND IS NOT RECOMMENDED                                 | -->
<!-- =================================================================================== -->
<robot name="widowxl">
  <material name="interbotix_black">
    <texture filename="package://interbotix_xsarm_descriptions/meshes/interbotix_black.png"/>
  </material>
  <link name="widowxl/base_link">
    <visual>
      <origin rpy="0 0 0" xyz="0 0 0"/>
      <geometry>
        <mesh filename="package://interbotix_xsarm_descriptions/meshes/meshes_widowxl/base_link.stl" scale="0.001 0.001 0.001"/>
      </geometry>
      <material name="interbotix_black"/>
    </visual>
    <collision>
      <origin rpy="0 0 0" xyz="0 0 0"/>
      <geometry>
        <mesh filename="package://interbotix_xsarm_descriptions/meshes/meshes_widowxl/base_link.stl" scale="0.001 0.001 0.001"/>
      </geometry>
    </collision>
  </link>
  <joint name="waist" type="revolute">
    <axis xyz="0 0 1"/>
    <limit effort="10" lower="-3.1415" upper="3.1415" velocity="1.571"/>
    <origin rpy="0 0 0" xyz="0 0 0.167"/>
    <parent link="widowxl/base_link"/>
    <child link="widowxl/shoulder_link"/>
    <dynamics friction="0.1"/>
  </joint>
  <transmission name="trans_waist">
    <type>transmission_interface/SimpleTransmission</type>
    <joint name="waist">
      <hardwareInterface>hardware_interface/EffortJointInterface</hardwareInterface>
    </joint>
    <actuator name="waist_motor">
      <mechanicalReduction>1</mechanicalReduction>
    </actuator>
  </transmission>
  <link name="widowxl/shoulder_link">
    <visual>
      <origin rpy="0 0 0" xyz="0 0 -0.167"/>
      <geometry>
        <mesh filename="package://interbotix_xsarm_descriptions/meshes/meshes_widowxl/shoulder_link__4__1.stl" scale="0.001 0.001 0.001"/>
      </geometry>
      <material name="interbotix_black"/>
    </visual>
    <collision>
      <origin rpy="0 0 0" xyz="0 0 -0.167"/>
      <geometry>
        <mesh filename="package://interbotix_xsarm_descriptions/meshes/meshes_widowxl/shoulder_link__4__1.stl" scale="0.001 0.001 0.001"/>
      </geometry>
    </collision>
    <inertial>
      <origin rpy="0 0 0" xyz="0 0 -0.167"/>
      <mass value="0.480879"/>
      <inertia ixx="0.0003790000" ixy="0.0000000022" ixz="-0.0000003561" iyy="0.0005557000" iyz="0.0000012245" izz="0.0005889000"/>
    </inertial>
  </link>
  <joint name="shoulder" type="revolute">
    <axis xyz="0 1 0"/>
    <limit effort="20" lower="-1.571" upper="1.571" velocity="1.571"/>
    <origin rpy="0 0 0" xyz="0 0 0.0367"/>
    <parent link="widowxl/shoulder_link"/>
    <child link="widowxl/upper_arm_link"/>
    <dynamics friction="0.1"/>
  </joint>
  <transmission name="trans_shoulder">
    <type>transmission_interface/SimpleTransmission</type>
    <joint name="shoulder">
      <hardwareInterface>hardware_interface/EffortJointInterface</hardwareInterface>
    </joint>
    <actuator name="shoulder_motor">
      <mechanicalReduction>1</mechanicalReduction>
    </actuator>
  </transmission>
  <link name="widowxl/upper_arm_link">
    <visual>
      <origin rpy="0 0 0" xyz="0 0 -0.2"/>
      <geometry>
        <mesh filename="package://interbotix_xsarm_descriptions/meshes/meshes_widowxl/biceps_link_1.stl" scale="0.001 0.001 0.001"/>
      </geometry>
      <material name="interbotix_black"/>
    </visual>
    <collision>
      <origin rpy="0 0 0" xyz="0 0 -0.2"/>
      <geometry>
        <mesh filename="package://interbotix_xsarm_descriptions/meshes/meshes_widowxl/biceps_link_1.stl" scale="0.001 0.001 0.001"/>
      </geometry>
    </collision>
    <inertial>
      <origin rpy="0 0 0" xyz="0 0 -0.2"/>
      <mass value="0.430811"/>
      <inertia ixx="0.0034630000" ixy="-0.0000000001" ixz="-0.0000000002" iyy="0.0035870000" iyz="0.0004272000" izz="0.0004566000"/>
    </inertial>
  </link>
  <joint name="elbow" type="revolute">
    <axis xyz="0 1 0"/>
    <limit effort="15" lower="-1.571" upper="1.571" velocity="1.571"/>
    <origin rpy="0 0 0" xyz="0.05 0 0.145"/>
    <parent link="widowxl/upper_arm_link"/>
    <child link="widowxl/forearm_link"/>
    <dynamics friction="0.1"/>
  </joint>
  <transmission name="trans_elbow">
    <type>transmission_interface/SimpleTransmission</type>
    <joint name="elbow">
      <hardwareInterface>hardware_interface/EffortJointInterface</hardwareInterface>
    </joint>
    <actuator name="elbow_motor">
      <mechanicalReduction>1</mechanicalReduction>
    </actuator>
  </transmission>
  <link name="widowxl/forearm_link">
    <visual>
      <origin rpy="0 0 0" xyz="-0.05 0 -0.347"/>
      <geometry>
        <mesh filename="package://interbotix_xsarm_descriptions/meshes/meshes_widowxl/forearm_link_1.stl" scale="0.001 0.001 0.001"/>
      </geometry>
      <material name="interbotix_black"/>
    </visual>
    <collision>
      <origin rpy="0 0 0" xyz="-0.05 0 -0.347"/>
      <geometry>
        <mesh filename="package://interbotix_xsarm_descriptions/meshes/meshes_widowxl/forearm_link_1.stl" scale="0.001 0.001 0.001"/>
      </geometry>
    </collision>
    <inertial>
      <origin rpy="0 0 0" xyz="-0.05 0 -0.347"/>
      <mass value="0.297673"/>
      <inertia ixx="0.0021760000" ixy="-0.0000030658" ixz="0.0000000000" iyy="0.0000575700" iyz="0.0000000000" izz="0.0021860000"/>
    </inertial>
  </link>
  <joint name="wrist_angle" type="revolute">
    <axis xyz="0 1 0"/>
    <limit effort="5" lower="-1.745" upper="1.745" velocity="1.571"/>
    <origin rpy="0 0 0" xyz="0.15 0 0"/>
    <parent link="widowxl/forearm_link"/>
    <child link="widowxl/wrist_link"/>
    <dynamics friction="0.1"/>
  </joint>
  <transmission name="trans_wrist_angle">
    <type>transmission_interface/SimpleTransmission</type>
    <joint name="wrist_angle">
      <hardwareInterface>hardware_interface/EffortJointInterface</hardwareInterface>
    </joint>
    <actuator name="wrist_angle_motor">
      <mechanicalReduction>1</mechanicalReduction>
    </actuator>
  </transmission>
  <link name="widowxl/wrist_link">
    <visual>
      <origin rpy="0 0 0" xyz="-0.2 0 -0.347"/>
      <geometry>
        <mesh filename="package://interbotix_xsarm_descriptions/meshes/meshes_widowxl/wrist_1_1.stl" scale="0.001 0.001 0.001"/>
      </geometry>
      <material name="interbotix_black"/>
    </visual>
    <collision>
      <origin rpy="0 0 0" xyz="-0.2 0 -0.347"/>
      <geometry>
        <mesh filename="package://interbotix_xsarm_descriptions/meshes/meshes_widowxl/wrist_1_1.stl" scale="0.001 0.001 0.001"/>
      </geometry>
    </collision>
    <inertial>
      <origin rpy="0 0 0" xyz="-0.2 0 -0.347"/>
      <mass value="0.084957"/>
      <inertia ixx="0.0000308200" ixy="0.0000000191" ixz="0.0000000023" iyy="0.0000282200" iyz="0.0000025481" izz="0.0000315200"/>
    </inertial>
  </link>
  <joint name="wrist_rotate" type="revolute">
    <axis xyz="1 0 0"/>
    <limit effort="1" lower="-2.167" upper="2.167" velocity="1.571"/>
    <origin rpy="0 0 0" xyz="0.08 0 0"/>
    <parent link="widowxl/wrist_link"/>
    <child link="widowxl/wrist_2_link"/>
    <dynamics friction="0.1"/>
  </joint>
  <transmission name="trans_wrist_rotate">
    <type>transmission_interface/SimpleTransmission</type>
    <joint name="wrist_rotate">
      <hardwareInterface>hardware_interface/EffortJointInterface</hardwareInterface>
    </joint>
    <actuator name="wrist_rotate_motor">
      <mechanicalReduction>1</mechanicalReduction>
    </actuator>
  </transmission>
  <link name="widowxl/wrist_2_link">
    <visual>
      <origin rpy="0 0 0" xyz="-0.28 0.0 -0.347"/>
      <geometry>
        <mesh filename="package://interbotix_xsarm_descriptions/meshes/meshes_widowxl/wrist_2_1.stl" scale="0.001 0.001 0.001"/>
      </geometry>
      <material name="interbotix_black"/>
    </visual>
    <collision>
      <origin rpy="0 0 0" xyz="-0.28 0.0 -0.347"/>
      <geometry>
        <mesh filename="package://interbotix_xsarm_descriptions/meshes/meshes_widowxl/wrist_2_1.stl" scale="0.001 0.001 0.001"/>
      </geometry>
    </collision>
    <inertial>
      <origin rpy="0 0 0" xyz="-0.28 0.0 -0.347"/>
      <mass value="0.072885"/>
      <inertia ixx="0.0000253700" ixy="0.0000000000" ixz="0.0000000000" iyy="0.0000183600" iyz="0.0000004340" izz="0.0000167400"/>
    </inertial>
  </link>
  <joint name="ee_arm" type="fixed">
    <axis xyz="1 0 0"/>
    <origin rpy="0 0 0" xyz="0.043 0 0"/>
    <parent link="widowxl/wrist_2_link"/>
    <child link="widowxl/ee_arm_link"/>
  </joint>
  <link name="widowxl/ee_arm_link">
    <inertial>
      <mass value="0.001"/>
      <inertia ixx="0.001" ixy="0" ixz="0" iyy="0.001" iyz="0" izz="0.001"/>
    </inertial>
  </link>
  <joint name="gripper" type="continuous">
    <axis xyz="1 0 0"/>
    <limit effort="1" velocity="3.14159265359"/>
    <origin rpy="0 0 0" xyz="0.0055 0 0"/>
    <parent link="widowxl/ee_arm_link"/>
    <child link="widowxl/gripper_prop_link"/>
    <dynamics friction="0.1"/>
  </joint>
  <transmission name="trans_gripper">
    <type>transmission_interface/SimpleTransmission</type>
    <joint name="gripper">
      <hardwareInterface>hardware_interface/EffortJointInterface</hardwareInterface>
    </joint>
    <actuator name="gripper_motor">
      <mechanicalReduction>1</mechanicalReduction>
    </actuator>
  </transmission>
  <link name="widowxl/gripper_prop_link">
    <inertial>
      <mass value="0.00434"/>
      <inertia ixx="0.0000005923" ixy="0.0000000000" ixz="0.0000003195" iyy="0.0000011156" iyz="-0.0000000004" izz="0.0000005743"/>
    </inertial>
  </link>
  <!-- If the AR tag is being used, then add the AR tag mount -->
  <!-- If the gripper bar is being used, then also add the gripper bar -->
  <joint name="gripper_bar" type="fixed">
    <axis xyz="1 0 0"/>
    <origin rpy="0 0 0" xyz="0 0 0"/>
    <parent link="widowxl/ee_arm_link"/>
    <child link="widowxl/gripper_bar_link"/>
  </joint>
  <link name="widowxl/gripper_bar_link">
    <inertial>
      <origin rpy="0 0 1.57079632679" xyz="0.0096870000 0.0000008177 0.0049620000"/>
      <mass value="0.034199"/>
      <inertia ixx="0.0000074125" ixy="-0.0000000008" ixz="-0.0000000006" iyy="0.0000284300" iyz="-0.0000013889" izz="0.0000286000"/>
    </inertial>
  </link>
  <joint name="ee_bar" type="fixed">
    <axis xyz="1 0 0"/>
    <origin rpy="0 0 0" xyz="0.023 0 0"/>
    <parent link="widowxl/gripper_bar_link"/>
    <child link="widowxl/fingers_link"/>
  </joint>
  <link name="widowxl/fingers_link">
    <inertial>
      <mass value="0.001"/>
      <inertia ixx="0.001" ixy="0" ixz="0" iyy="0.001" iyz="0" izz="0.001"/>
    </inertial>
  </link>
  <!-- If the gripper fingers are being used, add those as well -->
  <joint name="left_finger" type="prismatic">
    <axis xyz="0 1 0"/>
    <limit effort="5" lower="0.015" upper="0.037" velocity="1"/>
    <origin rpy="0 0 0" xyz="0 0 0"/>
    <parent link="widowxl/fingers_link"/>
    <child link="widowxl/left_finger_link"/>
    <dynamics friction="0.1"/>
  </joint>
  <transmission name="trans_left_finger">
    <type>transmission_interface/SimpleTransmission</type>
    <joint name="left_finger">
      <hardwareInterface>hardware_interface/EffortJointInterface</hardwareInterface>
    </joint>
    <actuator name="left_finger_motor">
      <mechanicalReduction>1</mechanicalReduction>
    </actuator>
  </transmission>
  <link name="widowxl/left_finger_link">
    <visual>
      <origin rpy="0 0 0" xyz="-0.346 -0.007 -0.347"/>
      <geometry>
        <mesh filename="package://interbotix_xsarm_descriptions/meshes/meshes_widowxl/finger.stl" scale="0.001 0.001 0.001"/>
      </geometry>
      <material name="interbotix_black"/>
    </visual>
    <collision>
      <origin rpy="0 0 0" xyz="-0.346 -0.007 -0.347"/>
      <geometry>
        <mesh filename="package://interbotix_xsarm_descriptions/meshes/meshes_widowxl/finger.stl" scale="0.001 0.001 0.001"/>
      </geometry>
    </collision>
    <inertial>
      <origin rpy="0 0 0" xyz="-0.346 -0.007 -0.347"/>
      <mass value="0.016246"/>
      <inertia ixx="0.0000047310" ixy="-0.0000004560" ixz="0.0000000000" iyy="0.0000015506" iyz="0.0000000000" izz="0.0000037467"/>
    </inertial>
  </link>
  <joint name="right_finger" type="prismatic">
    <axis xyz="0 1 0"/>
    <limit effort="5" lower="-0.037" upper="-0.015" velocity="1"/>
    <origin rpy="0 0 0" xyz="0 0 0"/>
    <parent link="widowxl/fingers_link"/>
    <child link="widowxl/right_finger_link"/>
    <dynamics friction="0.1"/>
    <mimic joint="left_finger" multiplier="-1" offset="0"/>
  </joint>
  <transmission name="trans_right_finger">
    <type>transmission_interface/SimpleTransmission</type>
    <joint name="right_finger">
      <hardwareInterface>hardware_interface/EffortJointInterface</hardwareInterface>
    </joint>
    <actuator name="right_finger_motor">
      <mechanicalReduction>1</mechanicalReduction>
    </actuator>
  </transmission>
  <link name="widowxl/right_finger_link">
    <visual>
      <origin rpy="-3.1415 0 0" xyz="-0.346 0.007 0.345"/>
      <geometry>
        <mesh filename="package://interbotix_xsarm_descriptions/meshes/meshes_widowxl/finger.stl" scale="0.001 0.001 0.001"/>
      </geometry>
      <material name="interbotix_black"/>
    </visual>
    <collision>
      <origin rpy="-3.1415 0 0" xyz="-0.346 0.007 0.345"/>
      <geometry>
        <mesh filename="package://interbotix_xsarm_descriptions/meshes/meshes_widowxl/finger.stl" scale="0.001 0.001 0.001"/>
      </geometry>
    </collision>
    <inertial>
      <origin rpy="-3.1415 0 0" xyz="-0.346 0.007 0.345"/>
      <mass value="0.016246"/>
      <inertia ixx="0.0000047310" ixy="0.0000004560" ixz="0.0000000000" iyy="0.0000015506" iyz="0.0000000000" izz="0.0000037467"/>
    </inertial>
  </link>
  <joint name="ee_gripper" type="fixed">
    <axis xyz="1 0 0"/>
    <origin rpy="0 0 0" xyz="0.027575 0 0"/>
    <parent link="widowxl/fingers_link"/>
    <child link="widowxl/ee_gripper_link"/>
  </joint>
  <link name="widowxl/ee_gripper_link">
    <inertial>
      <mass value="0.001"/>
      <inertia ixx="0.001" ixy="0" ixz="0" iyy="0.001" iyz="0" izz="0.001"/>
    </inertial>
  </link>
</robot>

